Workbook

Sheet Metadados
A1: Variável | B1: Descrição
A2: Pais_Origem | B2: País de Origem do Café
A3: Tipo_Variedade | B3: Tipo de Variedade do Café
A4: Tipo_Processamento | B4: Tipo de Processamento que o Café foi produzido
A5: Faixa de Altitude | B5: Faixa de Altitude em que o Café foi cultivado
A6: Tipo_Qualidade | B6: Tipo de Qualidade de Café: Premium ou Normal

Sheet Base
A1: Pais_Origem | B1: Tipo_Variedade | C1: Tipo_Processamento | D1: Faixa de Altitude | E1: Tipo_Qualidade
A2: Others | B2: Catimor | C2: Washed / Wet | D2: 1300-1500 | E2: Premium
A3: Brazil | B3: Yellow Bourbon | C3: Semi-washed / Semi-pulped | D3: 1100-1300 | E3: Premium
A4: Mexico | B4: Typica | C4: Washed / Wet | D4: 1300-1500 | E4: Premium
A5: Guatemala | B5: Catuai | C5: Washed / Wet | D5: 1300-1500 | E5: Normal
A6: Guatemala | B6: Bourbon | C6: Washed / Wet | D6: 1300-1500 | E6: Normal
A7: Colombia | B7: Caturra | C7: Washed / Wet | D7: 1700-1900 | E7: Premium
A8: Mexico | B8: Typica | C8: Washed / Wet | D8: 1300-1500 | E8: Normal
A9: Mexico | B9: Typica | C9: Washed / Wet | D9: 1500-1700 | E9: Normal
A10: Guatemala | B10: Caturra | C10: Washed / Wet | D10: 1100-1300 | E10: Premium
A11: Brazil | B11: Mundo Novo | C11: Natural / Dry | D11: 900-1100 | E11: Normal
A12: Guatemala | B12: Catuai | C12: Washed / Wet | D12: 1300-1500 | E12: Normal
... A863: Tanzania, United Republic Of | B863: Bourbon | C863: Washed / Wet | D863: 1500-1700 | E863: Normal

Sheet Calculadora
B2: Precificação de Café para Cálculo de Garantias em Crédito | J2: Pais_Origem | K2: Tipo_Variedade | L2: Tipo_Processamento | M2: Faixa de Altitude
J3: Mexico | K3: Caturra | L3: Natural / Dry | M3: <700
B4: Dados do Café a ser dado como Garantia | J4: Guatemala | K4: Bourbon | L4: Washed / Wet | M4: 700-900
J5: Colombia | K5: Typica | L5: Pulped natural / honey | M5: 900-1100
B6: Pais de Origem | C6: Outros_Agrupado | J6: Brazil | K6: Outro | L6: Semi-washed / Semi-pulped | M6: 1100-1300
J7: Outros_Agrupado | K7: Catuai | M7: 1300-1500
B8: Tipo Variedade | C8: Catuai | J8: Taiwan | K8: Outras_Raras | M8: 1500-1700
J9: Honduras | K9: Mundo Novo | M9: 1700-1900
B10: Tipo Processamento | C10: Washed / Wet | J10: Costa Rica | K10: Catimor
J11: Tanzania, United Republic Of | K11: Yellow Bourbon
B12: Faixa de Altitude do Cultivo | C12: 700-900 | J12: China
J13: Others
J14: El Salvador
B15: Quantidade de Sacas de Café a ser dada como Garantia
B17: Qte de Sacas de 60kg | C17: 150
B20: Resultado
K21: Outro
B22: Valor Aproximado da Garantia | C22: =Análise!B155*(Análise!B153)+Análise!B156*(1-Análise!B153)*C17 -> 82661.907
B24: Valor máximo a ser liberado para empréstimo | C24: =C22*0.7 -> 57863.335

Sheet Análise
B2: 1) Quais as características do café aumentam a propensão dele ser do tipo Premium?
B4: 2) Para construir a calculadora solicitada conforme exemplo acima. A ideia é que o usuário informe as 5 primeiras informações (de País de Origem até a qte de Sacas de 60kg) e a calculadora possa fornecer as duas informações (Valor Aproximado da Garantia e Valor máximo a ser liberado para empréstimo).
B8: Contagem de Tipo_Qualidade | C8: Tipo_Qualidade | G8: Contagem de Tipo_Qualidade | H8: Tipo_Qualidade | L8: Contagem de Tipo_Qualidade | M8: Tipo_Qualidade | Q8: Contagem de Tipo_Qualidade | R8: Tipo_Qualidade
B9: Pais_Origem | C9: Normal | D9: Premium | E9: Total Result | G9: Tipo_Variedade | H9: Normal | I9: Premium | J9: Total Result | L9: Tipo_Processamento | M9: Normal | N9: Premium | O9: Total Result | Q9: Faixa de Altitude | R9: Normal | S9: Premium | T9: Total Result
B10: Brazil | C10: 40 | D10: 44 | E10: 84 | G10: Arusha | I10: 1 | J10: 1 | L10: Natural / Dry | M10: 59 | N10: 88 | O10: 147 | Q10: <700 | R10: 24 | S10: 14 | T10: 38
B11: China | C11: 5 | D11: 11 | E11: 16 | G11: Blue Mountain | H11: 1 | J11: 1 | L11: Pulped natural / honey | M11: 3 | N11: 6 | O11: 9 | Q11: 1100-1300 | R11: 123 | S11: 81 | T11: 204
B12: Colombia | C12: 18 | D12: 99 | E12: 117 | G12: Bourbon | H12: 97 | I12: 96 | J12: 193 | L12: Semi-washed / Semi-pulped | M12: 24 | N12: 26 | O12: 50 | Q12: 1300-1500 | R12: 118 | S12: 85 | T12: 203
B13: Costa Rica | C13: 16 | D13: 25 | E13: 41 | G13: Catimor | H13: 4 | I13: 15 | J13: 19 | L13: Washed / Wet | M13: 358 | N13: 298 | O13: 656 | Q13: 1500-1700 | R13: 64 | S13: 80 | T13: 144
B14: El Salvador | C14: 5 | D14: 10 | E14: 15 | G14: Catuai | H14: 41 | I14: 25 | J14: 66 | L14: Total Result | M14: 444 | N14: 418 | O14: 862 | Q14: 1700-1900 | R14: 41 | S14: 102 | T14: 143
B15: Ethiopia | D15: 10 | E15: 10 | G15: Caturra | H15: 76 | I15: 144 | J15: 220 | Q15: 700-900 | R15: 27 | S15: 21 | T15: 48
B16: Guatemala | C16: 68 | D16: 72 | E16: 140 | G16: Ethiopian Yirgacheffe | I16: 2 | J16: 2 | Q16: 900-1100 | R16: 47 | S16: 35 | T16: 82
B17: Haiti | C17: 4 | D17: 1 | E17: 5 | G17: Gesha | H17: 7 | I17: 4 | J17: 11 | Q17: Total Result | R17: 444 | S17: 418 | T17: 862
B18: Honduras | C18: 37 | D18: 10 | E18: 47 | G18: Java | H18: 1 | I18: 1 | J18: 2
B19: Indonesia | C19: 4 | D19: 6 | E19: 10 | G19: Mandheling | H19: 1 | J19: 1
B20: Kenya | D20: 1 | E20: 1 | G20: Mundo Novo | H20: 19 | I20: 6 | J20: 25
B21: Malawi | C21: 9 | D21: 1 | E21: 10 | G21: Outro | H21: 45 | I21: 44 | J21: 89
B22: Mexico | C22: 164 | D22: 59 | E22: 223 | G22: Pacamara | H22: 3 | I22: 4 | J22: 7
B23: Myanmar | C23: 2 | E23: 2 | G23: Pacas | H23: 7 | I23: 5 | J23: 12
B24: Nicaragua | C24: 8 | D24: 2 | E24: 10 | G24: Peaberry | I24: 1 | J24: 1
B25: Others | C25: 6 | D25: 10 | E25: 16 | G25: Ruiru 11 | I25: 1 | J25: 1
B26: Peru | C26: 2 | E26: 2 | G26: Sumatra | I26: 2 | J26: 2
B27: Taiwan | C27: 32 | D27: 23 | E27: 55 | G27: Typica | H27: 135 | I27: 57 | J27: 192
B28: Tanzania, United Republic Of | C28: 20 | D28: 14 | E28: 34 | G28: Yellow Bourbon | H28: 7 | I28: 10 | J28: 17
B29: Thailand | C29: 1 | D29: 7 | E29: 8 | G29: Total Result | H29: 444 | I29: 418 | J29: 862
B30: Uganda | D30: 8 | E30: 8
B31: United States | C31: 1 | D31: 3 | E31: 4
B32: Vietnam | C32: 2 | D32: 2 | E32: 4
B33: Total Result | C33: 444 | D33: 418 | E33: 862
A36: Information Value
A38: Contagem de Tipo_Qualidade | B38: Tipo_Qualidade
A39: Tipo_Processamento | B39: Normal | C39: Premium | D39: Total Result | E39: Freq | F39: Premium | G39: Normal | H39: ODD | I39: IV
A40: Natural / Dry | B40: 59 | C40: 88 | D40: 147 | E40: =D40/$D$44 -> 0.17053364 | F40: =C40/$C$44 -> 0.21052632 | G40: =B40/$B$44 -> 0.13288288 | H40: =F40/G40 -> 1.5842997 | I40: =(F40-G40)*LN(H40) -> 0.035727043
A41: Pulped natural / honey | B41: 3 | C41: 6 | D41: 9 | E41: =D41/$D$44 -> 0.010440835 | F41: =C41/$C$44 -> 0.014354067 | G41: =B41/$B$44 -> 0.0067567568 | H41: =F41/G41 -> 2.1244019 | I41: =(F41-G41)*LN(H41) -> 0.0057244996
A42: Semi-washed / Semi-pulped | B42: 24 | C42: 26 | D42: 50 | E42: =D42/$D$44 -> 0.05800464 | F42: =C42/$C$44 -> 0.062200957 | G42: =B42/$B$44 -> 0.054054054 | H42: =F42/G42 -> 1.1507177 | I42: =(F42-G42)*LN(H42) -> 0.0011437098
A43: Washed / Wet | B43: 358 | C43: 298 | D43: 656 | E43: =D43/$D$44 -> 0.76102088 | F43: =C43/$C$44 -> 0.71291866 | G43: =B43/$B$44 -> 0.80630631 | H43: =F43/G43 -> 0.88417845 | I43: =(F43-G43)*LN(H43) -> 0.01149568
A44: Total Result | B44: 444 | C44: 418 | D44: 862 | I44: =SUM(I40:I43) -> 0.054090933
I45: Baixo poder preditivo
A47: Contagem de Tipo_Qualidade | B47: Tipo_Qualidade
A48: Faixa de Altitude | B48: Normal | C48: Premium | D48: Total Result | E48: Freq | F48: Premium | G48: Normal | H48: ODD | I48: IV
A49: <700 | B49: 24 | C49: 14 | D49: 38 | E49: =D49/$D$56 -> 0.044083527 | F49: =C49/$C$56 -> 0.033492823 | G49: =B49/$B$56 -> 0.054054054 | H49: =F49/G49 -> 0.61961722 | I49: =(F49-G49)*LN(H49) -> 0.0098417026
...

Sheet Validação
A1: Validação do modelo: probabilidade prevista (WOE) x probabilidade real observada
A3: Pais | B3: Variedade | C3: Processamento | D3: Altitude | E3: N (registros) | F3: P(Premium) Real | G3: P(Premium) Modelo | H3: Diferença (Modelo - Real)
A4: Colombia | B4: Caturra | C4: Washed / Wet | D4: 1700-1900 | E4: 65 | F4: 0.8615 | G4: =EXP(I4)/(1+EXP(I4)) -> 0.95308856 | H4: =G4-F4 -> 0.091588556 | I4: =Análise!$B$145+VLOOKUP(A4,Análise!$A$116:$F$127,6,0)+VLOOKUP(B4,Análise!$A$133:$F$141,6,0)+VLOOKUP(C4,Análise!$A$95:$F$98,6,0)+VLOOKUP(D4,Análise!$A$104:$F$110,6,0) -> 3.0114462
A5: Guatemala | B5: Bourbon | C5: Washed / Wet | D5: 1300-1500 | E5: 38 | F5: 0.4737 | G5: =EXP(I5)/(1+EXP(I5)) -> 0.37167905 | H5: =G5-F5 -> -0.10202095 | I5: =Análise!$B$145+VLOOKUP(A5,Análise!$A$116:$F$127,6,0)+VLOOKUP(B5,Análise!$A$133:$F$141,6,0)+VLOOKUP(C5,Análise!$A$95:$F$98,6,0)+VLOOKUP(D5,Análise!$A$104:$F$110,6,0) -> -0.52502037
A6: Mexico | B6: Typica | C6: Washed / Wet | D6: 1100-1300 | E6: 36 | F6: 0.1667 | G6: =EXP(I6)/(1+EXP(I6)) -> 0.072690928 | H6: =G6-F6 -> -0.094009072 | I6: =Análise!$B$145+VLOOKUP(A6,Análise!$A$116:$F$127,6,0)+VLOOKUP(B6,Análise!$A$133:$F$141,6,0)+VLOOKUP(C6,Análise!$A$95:$F$98,6,0)+VLOOKUP(D6,Análise!$A$104:$F$110,6,0) -> -2.5460703
A7: Mexico | B7: Typica | C7: Washed / Wet | D7: 1300-1500 | E7: 32 | F7: 0.2188 | G7: =EXP(I7)/(1+EXP(I7)) -> 0.078974079 | H7: =G7-F7 -> -0.13982592 | I7: =Análise!$B$145+VLOOKUP(A7,Análise!$A$116:$F$127,6,0)+VLOOKUP(B7,Análise!$A$133:$F$141,6,0)+VLOOKUP(C7,Análise!$A$95:$F$98,6,0)+VLOOKUP(D7,Análise!$A$104:$F$110,6,0) -> -2.4563685
A8: Mexico | B8: Typica | C8: Washed / Wet | D8: 1500-1700 | E8: 21 | F8: 0.2857 | G8: =EXP(I8)/(1+EXP(I8)) -> 0.12952202 | H8: =G8-F8 -> -0.15617798 | I8: =Análise!$B$145+VLOOKUP(A8,Análise!$A$116:$F$127,6,0)+VLOOKUP(B8,Análise!$A$133:$F$141,6,0)+VLOOKUP(C8,Análise!$A$95:$F$98,6,0)+VLOOKUP(D8,Análise!$A$104:$F$110,6,0) -> -1.9051916
A9: Guatemala | B9: Bourbon | C9: Washed / Wet | D9: 1700-1900 | E9: 18 | F9: 0.3889 | G9: =EXP(I9)/(1+EXP(I9)) -> 0.6713757 | H9: =G9-F9 -> 0.2824757 | I9: =Análise!$B$145+VLOOKUP(A9,Análise!$A$116:$F$127,6,0)+VLOOKUP(B9,Análise!$A$133:$F$141,6,0)+VLOOKUP(C9,Análise!$A$95:$F$98,6,0)+VLOOKUP(D9,Análise!$A$104:$F$110,6,0) -> 0.71441374
A10: Guatemala | B10: Bourbon | C10: Washed / Wet | D10: 1500-1700 | E10: 16 | F10: 0.6875 | G10: =EXP(I10)/(1+EXP(I10)) -> 0.50653876 | H10: =G10-F10 -> -0.18096124 | I10: =Análise!$B$145+VLOOKUP(A10,Análise!$A$116:$F$127,6,0)+VLOOKUP(B10,Análise!$A$133:$F$141,6,0)+VLOOKUP(C10,Análise!$A$95:$F$98,6,0)+VLOOKUP(D10,Análise!$A$104:$F$110,6,0) -> 0.026156548
A11: Colombia | B11: Caturra | C11: Washed / Wet | D11: 1500-1700 | E11: 15 | F11: 0.8 | G11: =EXP(I11)/(1+EXP(I11)) -> 0.91077942 | H11: =G11-F11 -> 0.11077942 | I11: =Análise!$B$145+VLOOKUP(A11,Análise!$A$116:$F$127,6,0)+VLOOKUP(B11,Análise!$A$133:$F$141,6,0)+VLOOKUP(C11,Análise!$A$95:$F$98,6,0)+VLOOKUP(D11,Análise!$A$104:$F$110,6,0) -> 2.323189
A12: Guatemala | B12: Bourbon | C12: Washed / Wet | D12: 1100-1300 | E12: 15 | F12: 0.5333 | G12: =EXP(I12)/(1+EXP(I12)) -> 0.35098275 | H12: =G12-F12 -> -0.18231725 | I12: =Análise!$B$145+VLOOKUP(A12,Análise!$A$116:$F$127,6,0)+VLOOKUP(B12,Análise!$A$133:$F$141,6,0)+VLOOKUP(C12,Análise!$A$95:$F$98,6,0)+VLOOKUP(D12,Análise!$A$104:$F$110,6,0) -> -0.6147222
A13: Honduras | B13: Catuai | C13: Washed / Wet | D13: 1300-1500 | E13: 15 | F13: 0.1333 | G13: =EXP(I13)/(1+EXP(I13)) -> 0.085111109 | H13: =G13-F13 -> -0.048188891 | I13: =Análise!$B$145+VLOOKUP(A13,Análise!$A$116:$F$127,6,0)+VLOOKUP(B13,Análise!$A$133:$F$141,6,0)+VLOOKUP(C13,Análise!$A$95:$F$98,6,0)+VLOOKUP(D13,Análise!$A$104:$F$110,6,0) -> -2.3748451
A15: Erro absoluto médio (MAE): | H15: =SUMPRODUCT(ABS(G4:G13-F4:F13))/COUNT(G4:G13) -> 0.1388345
